Workbook

Sheet Bid Details
B5: BID DETAILS
B7: RFQ NAME: | E7: OPEN DATE: | F7: CLOSE DATE:
B8: 49466087 CRFQ1
B9: COMPANY NAME: | C9: VENDOR NUMBER: | E9: QUOTE NUMBER:
B10: [Enter company name here.] | C10: [Enter vendor number here.] | E10: [Enter quote number here.]
B12: ITEM NAME | C12: UOM | D12: DESIRED QUANTITY | E12: PRICE PER UNIT | F12: QUOTED PRICE
B13: Site Establishment | C13: Each (Ea) | D13: 0 | E13: 0 | F13: =E13*D13 -> 0
B14: Boundary Surveying | C14: Each (Ea) | D14: 0 | E14: 0 | F14: =E14*D14 -> 0
B15: Traffic & Pedestrian Management | C15: Each (Ea) | D15: 0 | E15: 0 | F15: =E15*D15 -> 0
B16: 50mm Duct Installation | C16: Metre | D16: 0 | E16: 0 | F16: =E16*D16 -> 0
B17: 1 x 32mm (within Existing Carrier/Private Network) | C17: Metre | D17: 0 | E17: 0 | F17: =E17*D17 -> 0
B18: Telstra-Optus Breakout - Core Drill & Jackmoon Seal | C18: Each (Ea) | D18: 0 | E18: 0 | F18: =E18*D18 -> 0
B19: Telstra-Optus Breakout - P100 with 4xP32 Subduct | C19: Metre | D19: 0 | E19: 0 | F19: =E19*D19 -> 0
B20: P4 Pit (Optus Approved) – S&I | C20: Each (Ea) | D20: 0 | E20: 0 | F20: =E20*D20 -> 0
B21: P4 Pit (Optus Approved) – Over Existing Network S&I | C21: Each (Ea) | D21: 0 | E21: 0 | F21: =E21*D21 -> 0
B22: P5 Pit (Optus Approved) – S&I | C22: Each (Ea) | D22: 0 | E22: 0 | F22: =E22*D22 -> 0
B23: P5 Pit (Optus Approved) – Over Existing Network S&I | C23: Each (Ea) | D23: 0 | E23: 0 | F23: =E23*D23 -> 0
B24: A8 Pit (Optus Approved) – S&I | C24: Each (Ea) | D24: 0 | E24: 0 | F24: =E24*D24 -> 0
... B73: Testing of Cable (All Spliced Fibres - Bi-directional at 1310nm & 1550nm) | C73: Each (Ea) | D73: 0 | E73: 0 | F73: =E73*D73 -> 0
C74: STANDARD SUBTOTAL: | F74: =SUM($F13:$F73) -> 0
B75: NON-STANDARD ITEM NAME
B76: De-Watering of Manholes | C76: Each (Ea) | D76: 0 | E76: 0 | F76: =E76*D76 -> 0
B77: 100mm Duct Installation | C77: Metre | D77: 0 | E77: 0 | F77: =E77*D77 -> 0
B78: A8 Pit & Sika Lid S&I | C78: Each (Ea) | D78: 0 | E78: 0 | F78: =E78*D78 -> 0
B79: A10 Pit & Sika Lid S&I | C79: Each (Ea) | D79: 0 | E79: 0 | F79: =E79*D79 -> 0
B80: P5 Pit (Lockable Concrete/Paver Infill Lid) S&I | C80: Each (Ea) | D80: 0 | E80: 0 | F80: =E80*D80 -> 0
B81: P5 Pit (Lockable Concrete/Paver Infill Lid) over Existing Network S&I | C81: Each (Ea) | D81: 0 | E81: 0 | F81: =E81*D81 -> 0
B82: P8 Pit (over Existing Network) S&I | C82: Each (Ea) | D82: 0 | E82: 0 | F82: =E82*D82 -> 0
B83: Dig Down (over Existing Optus IOF Network) | C83: Each (Ea) | D83: 0 | E83: 0 | F83: =E83*D83 -> 0
B84: Insitu Pit S&I (with Sika lid) | C84: Each (Ea) | D84: 0 | E84: 0 | F84: =E84*D84 -> 0
B85: Upgrade P5 Pit to A8 Pit - Install Only | C85: Each (Ea) | D85: 0 | E85: 0 | F85: =E85*D85 -> 0
B86: Upgrade P5 Pit to A10 Pit - Install Only | C86: Each (Ea) | D86: 0 | E86: 0 | F86: =E86*D86 -> 0
B87: Upgrade P8 Pit to A10 Pit - Install Only | C87: Each (Ea) | D87: 0 | E87: 0 | F87: =E87*D87 -> 0
... B102: Pole Guards | C102: Each (Ea) | D102: 0 | E102: 0 | F102: =E102*D102 -> 0
C103: NON-STANDARD SUBTOTAL: | F103: =SUM($F76:$F102) -> 0
B104: SPECIAL ITEM NAME – Project Specific
F105: 0
F106: 0
F107: 0
F108: 0
...

Sheet Import Data
A1: RFQ-Reference | B1: COMPANY NAME | C1: VENDOR NUMBER | D1: QUOTE NUMBER | E1: Quote-Price
A2: ='Bid Details'!B8 -> 49466087 CRFQ1 | B2: ='Bid Details'!B10 -> [Enter company name here.] | C2: ='Bid Details'!C10 -> [Enter vendor number here.] | D2: ='Bid Details'!E10 -> [Enter quote number here.] | E2: ='Bid Details'!F116 -> 0
